Workbook

Sheet China BEVs penetration rate
B1: BEV Sales | C1: BEV Cumulative | D1: PHEV Sales | E1: PHEV (Cumulative) | F1: NEV Sale | G1: NEV Cumulative | H1: PVS | I1: PVS Cumulative | J1: NEV/Total | K1: BEV/Total | L1: BEV (Cum)/PVS(Cum) | M1: NEV(Cum)/PVS(Cum)
A3: 41275 | H3: 1725500 | I3: =SUM($H$3:H3) -> 1725500
A4: 41306 | H4: 1111900 | I4: =SUM($H$3:H4) -> 2837400
A5: 41334 | H5: 1585500 | I5: =SUM($H$3:H5) -> 4422900
A6: 41365 | H6: 1441400 | I6: =SUM($H$3:H6) -> 5864300
A7: 41395 | H7: 1396900 | I7: =SUM($H$3:H7) -> 7261200
A8: 41426 | H8: 1403500 | I8: =SUM($H$3:H8) -> 8664700
A9: 41456 | H9: 1237600 | I9: =SUM($H$3:H9) -> 9902300
A10: 41487 | H10: 1353200 | I10: =SUM($H$3:H10) -> 11255500
A11: 41518 | H11: 1593500 | I11: =SUM($H$3:H11) -> 12849000
A12: 41548 | H12: 1605700 | I12: =SUM($H$3:H12) -> 14454700
A13: 41579 | H13: 1696300 | I13: =SUM($H$3:H13) -> 16151000
A14: 41609 | H14: 1462900 | I14: =SUM($H$3:H14) -> 17613900
A15: 2013 | C15: 14604 | E15: 3290 | F15: =SUM(C15+E15) -> 17894 | G15: =SUM($F15:F$17) -> 17894 | H15: =C15/G15 -> 0.81613949 | I15: 17613900 | L15: =C15/I15 -> 0.00082911791 | M15: =G15/I15 -> 0.0010159022
H16: =C16/G16 -> #DIV/0!
A17: 41640 | H17: =C17/G17 -> #DIV/0! | I17: =SUM($H$17:H17) -> #DIV/0!
A18: 41671 | H18: =C18/G18 -> #DIV/0! | I18: =SUM($H$17:H18) -> #DIV/0!
A19: 41699 | H19: =C19/G19 -> #DIV/0! | I19: =SUM($H$17:H19) -> #DIV/0!
A20: 41730 | H20: =C20/G20 -> #DIV/0! | I20: =SUM($H$17:H20) -> #DIV/0!
A21: 41760 | H21: =C21/G21 -> #DIV/0! | I21: =SUM($H$17:H21) -> #DIV/0!
A22: 41791 | H22: =C22/G22 -> #DIV/0! | I22: =SUM($H$17:H22) -> #DIV/0!
A23: 41821 | H23: =C23/G23 -> #DIV/0! | I23: =SUM($H$17:H23) -> #DIV/0!
A24: 41852 | H24: =C24/G24 -> #DIV/0! | I24: =SUM($H$17:H24) -> #DIV/0!
A25: 41883 | H25: =C25/G25 -> #DIV/0! | I25: =SUM($H$17:H25) -> #DIV/0!
A26: 41913 | H26: =C26/G26 -> #DIV/0! | I26: =SUM($H$17:H26) -> #DIV/0!
A27: 41944 | H27: =C27/G27 -> #DIV/0! | I27: =SUM($H$17:H27) -> #DIV/0!
A28: 41974 | H28: =C28/G28 -> #DIV/0! | I28: =SUM($H$17:H28) -> #DIV/0! | L28: =C31/I28 -> #DIV/0! | M28: =G31/I28 -> #DIV/0!
H29: =C29/G29 -> #DIV/0!
H30: =C30/G30 -> #DIV/0!
A31: 2014 | C31: 21732 | E31: 16129 | F31: =SUM(C31+E31) -> 37861 | G31: =SUM($F$17:F31) -> 37861 | H31: =C31/G31 -> 0.57399435 | I31: 19604338 | L31: =C31/I31 -> 0.0011085302 | M31: =G31/I31 -> 0.0019312562
H32: =C32/G32 -> #DIV/0!
A33: 42005 | H33: =C33/G33 -> #DIV/0! | I33: =SUM($H$33:H33) -> #DIV/0!
A34: 42036 | H34: =C34/G34 -> #DIV/0! | I34: =SUM($H$33:H34) -> #DIV/0!
A35: 42064 | H35: =C35/G35 -> #DIV/0! | I35: =SUM($H$33:H35) -> #DIV/0!
A36: 42095 | H36: =C36/G36 -> #DIV/0! | I36: =SUM($H$33:H36) -> #DIV/0!
A37: 42125 | H37: =C37/G37 -> #DIV/0! | I37: =SUM($H$33:H37) -> #DIV/0!
A38: 42156 | H38: =C38/G38 -> #DIV/0! | I38: =SUM($H$33:H38) -> #DIV/0!
A39: 42186 | H39: =C39/G39 -> #DIV/0! | I39: =SUM($H$33:H39) -> #DIV/0!
A40: 42217 | H40: =C40/G40 -> #DIV/0! | I40: =SUM($H$33:H40) -> #DIV/0!
A41: 42248 | H41: =C41/G41 -> #DIV/0! | I41: =SUM($H$33:H41) -> #DIV/0!
...

Sheet Ratio of Sales
C13: BEV | D13: PHEV | E13: Commercial
B14: 2016 | C14: 0.5 | D14: 0.16 | E14: 0.34
B15: 2017 | C15: 0.6 | D15: 0.14 | E15: 0.26
B16: 2018 | C16: 0.62 | D16: 0.2 | E16: 0.18
B17: 2019 | C17: 0.7 | D17: 0.18 | E17: 0.12

Sheet Annual Comparison
B1: BEV | C1: PHEV | D1: NEV | E1: Passenger Vehicle Sales | F1: BEV/PVS | G1: NEV/PVS | H1: BEV/PVS Annual Growth Rate
A2: 2013 | B2: 14604 | C2: 3290 | D2: =SUM(B2:C2) -> 17894 | E2: 17613900 | F2: =B2/E2 -> 0.00082911791 | G2: =D2/E2 -> 0.0010159022
A3: 2014 | B3: 21732 | C3: 16129 | D3: =SUM(B3:C3) -> 37861 | E3: 19604338 | F3: =B3/E3 -> 0.0011085302 | G3: =D3/E3 -> 0.0019312562 | H3: =(F3-F2)/F2 -> 0.33699941
A4: 2015 | B4: 52243 | C4: 59649 | D4: =SUM(B4:C4) -> 111892 | E4: 21060871 | F4: =B4/E4 -> 0.0024805717 | G4: =D4/E4 -> 0.0053127907 | H4: =(F4-F3)/F3 -> 1.2377124
A5: 2016 | B5: 167572 | C5: 72106 | D5: =SUM(B5:C5) -> 239678 | E5: 24159155 | F5: =B5/E5 -> 0.0069361697 | G5: =D5/E5 -> 0.009920794 | H5: =(F5-F4)/F4 -> 1.7961981
A6: 2017 | B6: 456097 | C6: 99868 | D6: =SUM(B6:C6) -> 555965 | E6: 24818264 | F6: =B6/E6 -> 0.018377474 | G6: =D6/E6 -> 0.022401446 | H6: =(F6-F5)/F5 -> 1.6495133
A7: 2018 | B7: 717414 | C7: 228954 | D7: =SUM(B7:C7) -> 946368 | E7: 23286084 | F7: =B7/E7 -> 0.030808701 | G7: =D7/E7 -> 0.040640925 | H7: =(F7-F6)/F6 -> 0.67643829
A8: 2019 | B8: 730509 | C8: 207537 | D8: =SUM(B8:C8) -> 938046 | E8: 21247801 | F8: =B8/E8 -> 0.034380452 | G8: =D8/E8 -> 0.04414791 | H8: =(F8-F7)/F7 -> 0.11593319

Sheet Battery Price 
A2: 2010 | B2: 1 | C2: 1160
A3: 2011 | B3: 2 | C3: 899
A4: 2012 | B4: 3 | C4: 707
A5: 2013 | B5: 4 | C5: 650
A6: 2014 | B6: 5 | C6: 577
A7: 2015 | B7: 6 | C7: 373
A8: 2016 | B8: 7 | C8: 288
A9: 2017 | B9: 8 | C9: 214
A10: 2018 | B10: 9 | C10: 176
A11: 2019 | B11: 10 | C11: 156
A12: Linear growth (0.9)
A13: 2020 | C13: =C11*$D$13 -> 140.4 | D13: 0.9
A14: 2021 | C14: =C13*$D$13 -> 126.36
A15: 2022 | C15: =C14*$D$13 -> 113.724
A16: 2023 | C16: =C15*$D$13 -> 102.3516
A17: 2024 | C17: =C16*$D$13 -> 92.11644
A18: 2025 | C18: =C17*$D$13 -> 82.904796
A21: simple exopnential growth
A22: 2020 | B22: 11 | C22: 130.48
A23: 2021 | B23: 12 | C23: 104.94
A24: 2022 | B24: 13 | C24: 84.39
A25: 2023 | B25: 14 | C25: 67.86
A26: 2024 | B26: 15 | C26: 54.57
A27: 2025 | B27: 16 | C27: 43.89
A28: 2026 | B28: 17 | C28: 35.29
A29: 2027 | B29: 18 | C29: 28.38
A30: 2028 | B30: 19 | C30: 22.83
A31: 2029 | B31: 20 | C31: 18.36
A32: 2030 | B32: 21 | C32: 14.76

Sheet Battery Installed Capacity
C3: ROEWE Model | D3: Sticker Price (RMB) | E3: National Subsidy | F3: Local Subsidy | G3: Liscense Plate Fee | H3: Purchase Tax | I3: Final Price
C4: ERX5 (EV400) | D4: 282000 | E4: 45000 | F4: 22000 | G4: 0 | H4: 0 | I4: 215000
C5: RX5 (2018) | D5: 158000 | E5: 0 | F5: 0 | G5: 89000 | H5: 13000 | I5: 260000
C9: BEV (Passenger) | D9: Standards | E9: 2018 | F9: 2019 | G9: Percentage Change
C10: Driving Range (KM) | D10: 150≤R<200 | E10: 15000 | F10: 0 | G10: =(F10-E10)/E10 -> -1
D11: 200≤R<250 | E11: 24000 | F11: 0 | G11: =(F11-E11)/E11 -> -1
D12: 250≤R<300 | E12: 34000 | F12: 18000 | G12: =(F12-E12)/E12 -> -0.47058824
D13: 300≤R<400 | E13: 45000 | F13: 18000 | G13: =(F13-E13)/E13 -> -0.6
D14: R≥400 | E14: 50000 | F14: 25000 | G14: =(F14-E14)/E14 -> -0.5
C15: Energy Density (Wh/kg) | D15: E<105 | E15: 0 | F15: 0 | G15: 0
D16: 105≤E<120 | E16: 6000 | F16: 0 | G16: =(F16-E16)/E16 -> -1
D17: 120≤E<125 | E17: 10000 | F17: 0 | G17: =(F17-E17)/E17 -> -1
D18: 125≤E<140 | E18: 10000 | F18: 8000 | G18: =(F18-E18)/E18 -> -0.2
D19: 140≤E<160 | E19: 11000 | F19: 9000 | G19: =(F19-E19)/E19 -> -0.18181818
D20: E≥160 | E20: 12000 | F20: 10000 | G20: =(F20-E20)/E20 -> -0.16666667

Sheet ABC class Vehicle Definition
B1: Wheelbase Length
B2: 乘用车级别：A00级乘用车：轴距在2米至2.3米之间，发动机排量小于1升
B3: A0级乘用车：轴距为2.3米至2.5米，排量为1升至1.5升。
B4: A级乘用车：轴距在2.5米至2.7米之间，排量约在1.6升至2.0升。
B5: B级乘用车：轴距约在2.7米至2.9米之间，排量从1.8升到2.4升。
B6: C级乘用车：轴距约在2.8米至3米之间，发动机排量大于2.4升

Sheet A00
C4: Chery eQ1
D5: 2019 | E5: 2020 | F5: 2021 | G5: 2022 | H5: 2023 | I5: 2024 | J5: 2025 | K5: 2026 | L5: 2027 | M5: 2028 | N5: 2029 | O5: 2030
C6: Retail Price | D6: 65000 | E6: =D6-((D16-E16)+(D17-E17)+(D18-E18)) -> 59928 | F6: =E6-((E16-F16)+(E17-F17)+(E18-F18)) -> 55343.2 | G6: =F6-((F16-G16)+(F17-G17)+(F18-G18)) -> 51196.88 | H6: =G6-((G16-H16)+(G17-H17)+(G18-H18)) -> 47445.192 | I6: =H6-((H16-I16)+(H17-I17)+(H18-I18)) -> 44048.673 | J6: =I6-((I16-J16)+(I17-J17)+(I18-J18)) -> 40971.806 | K6: =J6-((J16-K16)+(J17-K17)+(J18-K18)) -> 38182.625 | L6: =K6-((K16-L16)+(K17-L17)+(K18-L18)) -> 35652.362 | ... O6: =N6-((N16-O16)+(N17-O17)+(N18-O18)) -> 29368.852
C7: Purchase Tax | D7: 0 | E7: 0 | F7: =F6*0.1 -> 5534.32 | G7: =G6*0.1 -> 5119.688 | H7: =H6*0.1 -> 4744.5192 | I7: =I6*0.1 -> 4404.8673 | J7: =J6*0.1 -> 4097.1806 | K7: =K6*0.1 -> 3818.2625 | L7: =L6*0.1 -> 3565.2362 | M7: =M6*0.1 -> 3335.5126 | ... O7: =O6*0.1 -> 2936.8852
C8: Consumer Final Price | D8: =D6+D7 -> 65000 | E8: =E6+E7 -> 59928 | F8: =F6+F7 -> 60877.52 | G8: =G6+G7 -> 56316.568 | H8: =H6+H7 -> 52189.711 | I8: =I6+I7 -> 48453.54 | J8: =J6+J7 -> 45068.986 | K8: =K6+K7 -> 42000.887 | ... O8: =O6+O7 -> 32305.737
C9: Dealer Gross Profit(5%) | D9: =D6*0.05 -> 3250 | E9: =E6*0.05 -> 2996.4 | F9: =F6*0.05 -> 2767.16 | G9: =G6*0.05 -> 2559.844 | H9: =H6*0.05 -> 2372.2596 | I9: =I6*0.05 -> 2202.4336 | J9: =J6*0.05 -> 2048.5903 | K9: =K6*0.05 -> 1909.1312 | ... O9: =O6*0.05 -> 1468.4426
C10: Range (km) | D10: 301 | E10: 301 | F10: 301 | G10: 301 | H10: 301 | I10: 301 | J10: 301 | K10: 301 | L10: 301 | M10: 301 | N10: 301 | O10: 301
C11: Battery (kwh) | D11: 30.6 | E11: 30.6 | F11: 30.6 | G11: 30.6 | H11: 30.6 | I11: 30.6 | J11: 30.6 | K11: 30.6 | L11: 30.6 | M11: 30.6 | N11: 30.6 | O11: 30.6
C12: Battery Price/wh | D12: 1.2 | E12: =D12*0.9 -> 1.08 | F12: =E12*0.9 -> 0.972 | G12: =F12*0.9 -> 0.8748 | H12: =G12*0.9 -> 0.78732 | I12: =H12*0.9 -> 0.708588 | J12: =I12*0.9 -> 0.6377292 | K12: =J12*0.9 -> 0.57395628 | L12: =K12*0.9 -> 0.51656065 | ... O12: =N12*0.9 -> 0.37657272
C13: Subsidies | D13: 27000 | E13: 28000 | F13: 0 | G13: 0 | H13: 0 | I13: 0 | J13: 0 | K13: 0 | L13: 0 | M13: 0 | N13: 0 | O13: 0
C14: Auto Company Revenue | D14: =D6-D9+D13 -> 88750 | E14: =E6-E9+E13 -> 84931.6 | F14: =F6-F9+F13 -> 52576.04 | G14: =G6-G9+G13 -> 48637.036 | H14: =H6-H9+H13 -> 45072.932 | I14: =I6-I9+I13 -> 41846.239 | J14: =J6-J9+J13 -> 38923.215 | K14: =K6-K9+K13 -> 36273.494 | ... O14: =O6-O9+O13 -> 27900.41
C15: Revenue (after vat) | D15: =D14*0.87 -> 77212.5 | E15: =E14*0.87 -> 73890.492 | F15: =F14*0.87 -> 45741.155 | G15: =G14*0.87 -> 42314.221 | H15: =H14*0.87 -> 39213.451 | I15: =I14*0.87 -> 36406.228 | J15: =J14*0.87 -> 33863.197 | K15: =K14*0.87 -> 31557.94 | ... O15: =O14*0.87 -> 24273.356
C16: Power Battery System Cost | D16: =D12*1000*D11 -> 36720 | E16: =E12*1000*E11 -> 33048 | F16: =F12*1000*F11 -> 29743.2 | G16: =G12*1000*G11 -> 26768.88 | H16: =H12*1000*H11 -> 24091.992 | I16: =I12*1000*I11 -> 21682.793 | J16: =J12*1000*J11 -> 19514.514 | K16: =K12*1000*K11 -> 17563.062 | ... O16: =O12*1000*O11 -> 11523.125
C17: Electric Motor & Electric Controlling | D17: 5000 | E17: =D17-200 -> 4800 | F17: =E17-200 -> 4600 | G17: =F17-200 -> 4400 | H17: =G17-200 -> 4200 | I17: =H17-200 -> 4000 | J17: =I17-200 -> 3800 | K17: =J17-200 -> 3600 | L17: =K17-200 -> 3400 | ... O17: =N17-200 -> 2800
C18: Other Cost | D18: 12000 | E18: =D18*0.9 -> 10800 | F18: =E18*0.9 -> 9720 | G18: =F18*0.9 -> 8748 | H18: =G18*0.9 -> 7873.2 | I18: =H18*0.9 -> 7085.88 | J18: =I18*0.9 -> 6377.292 | K18: =J18*0.9 -> 5739.5628 | L18: =K18*0.9 -> 5165.6065 | ... O18: =N18*0.9 -> 3765.7272
C19: Profit Margin(BEV) | D19: =D15-D16-D17-D18 -> 23492.5 | E19: =E15-E16-E17-E18 -> 25242.492 | F19: =F15-F16-F17-F18 -> 1677.9548 | G19: =G15-G16-G17-G18 -> 2397.3413 | H19: =H15-H16-H17-H18 -> 3048.2592 | I19: =I15-I16-I17-I18 -> 3637.5553 | J19: =J15-J16-J17-J18 -> 4171.3917 | K19: =K15-K16-K17-K18 -> 4655.3146 | ... O19: =O15-O16-O17-O18 -> 6184.5041
C20: PM/Revenue | D20: =D19/D14 -> 0.26470423 | E20: =E19/E14 -> 0.29720966 | F20: =F19/F14 -> 0.031914819 | G20: =G19/G14 -> 0.049290449 | H20: =H19/H14 -> 0.067629485 | I20: =I19/I14 -> 0.086926695 | J20: =J19/J14 -> 0.10716976 | K20: =K19/K14 -> 0.12833929 | ... O20: =O19/O14 -> 0.22166356
C21: Chery QQ6
D22: 2019 | E22: 2020 | F22: 2021 | G22: 2022 | H22: 2023 | I22: 2024 | J22: 2025 | K22: 2026 | L22: 2027 | M22: 2028 | N22: 2029 | O22: 2030
C23: Retail Price | D23: 55000 | E23: =D23+(E29-D29)+(E30-D30) -> 55300 | F23: =E23+(F29-E29)+(F30-E30) -> 55606 | G23: =F23+(G29-F29)+(G30-F30) -> 55918.12 | H23: =G23+(H29-G29)+(H30-G30) -> 56236.482 | I23: =H23+(I29-H29)+(I30-H30) -> 56561.212 | J23: =I23+(J29-I29)+(J30-I30) -> 56892.436 | K23: =J23+(K29-J29)+(K30-J30) -> 57230.285 | L23: =K23+(L29-K29)+(L30-K30) -> 57574.891 | ... O23: =N23+(O29-N29)+(O30-N30) -> 58650.615
C24: Purchase Tax | D24: =D23*0.1 -> 5500 | E24: =E23*0.1 -> 5530 | F24: =F23*0.1 -> 5560.6 | G24: =G23*0.1 -> 5591.812 | H24: =H23*0.1 -> 5623.6482 | I24: =I23*0.1 -> 5656.1212 | J24: =J23*0.1 -> 5689.2436 | K24: =K23*0.1 -> 5723.0285 | ... O24: =O23*0.1 -> 5865.0615
C25: Consumer Final Price | D25: =D23+D24 -> 60500 | E25: =E23+E24 -> 60830 | F25: =F23+F24 -> 61166.6 | G25: =G23+G24 -> 61509.932 | H25: =H23+H24 -> 61860.131 | I25: =I23+I24 -> 62217.333 | J25: =J23+J24 -> 62581.68 | K25: =K23+K24 -> 62953.314 | ... O25: =O23+O24 -> 64515.676
C26: Dealer Gross Profit (5%) | D26: =D23*0.05 -> 2750 | E26: =E23*0.05 -> 2765 | F26: =F23*0.05 -> 2780.3 | G26: =G23*0.05 -> 2795.906 | H26: =H23*0.05 -> 2811.8241 | I26: =I23*0.05 -> 2828.0606 | J26: =J23*0.05 -> 2844.6218 | K26: =K23*0.05 -> 2861.5143 | ... O26: =O23*0.05 -> 2932.5307
C27: Auto Company Revenue | D27: =D23-D26 -> 52250 | E27: =E23-E26 -> 52535 | F27: =F23-F26 -> 52825.7 | G27: =G23-G26 -> 53122.214 | H27: =H23-H26 -> 53424.658 | I27: =I23-I26 -> 53733.151 | J27: =J23-J26 -> 54047.814 | K27: =K23-K26 -> 54368.771 | ... O27: =O23-O26 -> 55718.084
C28: Revenue (after vat) | D28: =D27*0.87 -> 45457.5 | E28: =E27*0.87 -> 45705.45 | F28: =F27*0.87 -> 45958.359 | G28: =G27*0.87 -> 46216.326 | H28: =H27*0.87 -> 46479.453 | I28: =I27*0.87 -> 46747.842 | J28: =J27*0.87 -> 47021.599 | K28: =K27*0.87 -> 47300.831 | ... O28: =O27*0.87 -> 48474.733
C29: Motor Cost | D29: 10000 | E29: =D29*1.02 -> 10200 | F29: =E29*1.02 -> 10404 | G29: =F29*1.02 -> 10612.08 | H29: =G29*1.02 -> 10824.322 | I29: =H29*1.02 -> 11040.808 | J29: =I29*1.02 -> 11261.624 | K29: =J29*1.02 -> 11486.857 | L29: =K29*1.02 -> 11716.594 | ... O29: =N29*1.02 -> 12433.743
C30: Transmission Cost | D30: 5000 | E30: =D30*1.02 -> 5100 | F30: =E30*1.02 -> 5202 | G30: =F30*1.02 -> 5306.04 | H30: =G30*1.02 -> 5412.1608 | I30: =H30*1.02 -> 5520.404 | J30: =I30*1.02 -> 5630.8121 | K30: =J30*1.02 -> 5743.4283 | L30: =K30*1.02 -> 5858.2969 | ... O30: =N30*1.02 -> 6216.8715
C31: 48V System Cost | D31: 0 | E31: 0 | F31: 0 | G31: 0 | H31: 0 | I31: 0 | J31: 0 | K31: 0 | L31: 0 | M31: 0 | N31: 0 | O31: 0
C32: Other Cost | D32: 16000 | E32: 16000 | F32: 16000 | G32: 16000 | H32: 16000 | I32: 16000 | J32: 16000 | K32: 16001 | L32: 16002 | M32: 16003 | N32: 16004 | O32: 16005
C33: Profit Margin(ICEV) | D33: =D28-D29-D30-D31-D32 -> 14457.5 | E33: =E28-E29-E30-E31-E32 -> 14405.45 | F33: =F28-F29-F30-F31-F32 -> 14352.359 | G33: =G28-G29-G30-G31-G32 -> 14298.206 | H33: =H28-H29-H30-H31-H32 -> 14242.97 | I33: =I28-I29-I30-I31-I32 -> 14186.63 | J33: =J28-J29-J30-J31-J32 -> 14129.162 | K33: =K28-K29-K30-K31-K32 -> 14069.546 | ... O33: =O28-O29-O30-O31-O32 -> 13819.118
C34: PM/Revenue | D34: =D33/D27 -> 0.27669856 | E34: =E33/E27 -> 0.27420672 | F34: =F33/F27 -> 0.27169274 | G34: =G33/G27 -> 0.26915682 | H34: =H33/H27 -> 0.26659918 | I34: =I33/I27 -> 0.26402006 | J34: =J33/J27 -> 0.26141968 | K34: =K33/K27 -> 0.25877991 | ... O34: =O33/O27 -> 0.24801855
D38: =D8-D25 -> 4500 | E38: =E8-E25 -> -902 | F38: =F8-F25 -> -289.08 | G38: =G8-G25 -> -5193.364 | H38: =H8-H25 -> -9670.4194 | I38: =I8-I25 -> -13763.793 | J38: =J8-J25 -> -17512.694 | K38: =K8-K25 -> -20952.426 | ... O38: =O8-O25 -> -32209.939

Sheet A00 class comparison 
P5: 2030
P6: =O6-((O16-P16)+(O17-P17)+(O18-P18)) -> -200
P7: =P6*0.1 -> -20
P8: =P6+P7 -> -220
P9: =P6*0.05 -> -10
P10: 301
P11: 30.6
P12: =O12*0.9 -> 0
P13: 0
P14: =P6-P9+P13 -> -190
P15: =P14*0.87 -> -165.3
P16: =P12*1000*P11 -> 0
P17: =O17-200 -> -200
P18: =O18*0.9 -> 0
P19: =P15-P16-P17-P18 -> 34.7
P20: =P19/P14 -> -0.18263158
P22: 2030
P23: =O23+(P29-O29)+(P30-O30) -> 0
P24: =P23*0.1 -> 0
P25: =P23+P24 -> 0
P26: =P23*0.05 -> 0
P27: =P23-P26 -> 0
P28: =P27*0.87 -> 0
P29: =O29*1.02 -> 0
P30: =O30*1.02 -> 0
P31: 0
P32: 16005
P33: =P28-P29-P30-P31-P32 -> -16005
P34: =P33/P27 -> #DIV/0!
P38: =P8-P25 -> -220
A42: ICEV BEV | C42: Chery eQ1 奇瑞eQ1 | E42: JAC iEV6E 江淮iEV6E | G42: SGMW E100 上汽通用宝骏E100 | I42: SGMW E200 上汽通用宝骏E200 | K42: Changan EV360 长安EV360 | M42: Zotye E200 众泰E200 | O42: Zhidou D2 知豆D2 | Q42: JMEV E200L 江铃E200L | S42: Changhe EC100 北汽昌河EC100 | U42: BAIC Lite 北汽新能源Lite
C43: 71900 | E43: 70500 | G43: 54800 | I43: 59800 | K43: 75800 | M43: 66900 | O43: 54800 | Q43: 53300 | S43: 47800 | U43: 118800
A44: Chery QQ6 奇瑞QQ6 | B44: 47400 | C44: 2025 | E44: 2025 | G44: 2020 | I44: 2022 | K44: 2026 | M44: 2024 | O44: 2020 | Q44: 2020 | S44: 2019 | U44: Post 2030
A46: Changhe Beidou Star 昌河北斗星 | B46: 53400 | C46: 2023 | E46: 2023 | G46: 2019 | I46: 2020 | K46: 2024 | M46: 2022 | O46: 2019 | Q46: 2019 | S46: 2019 | U46: Post 2030
A48: Changhe Beidou StarX5 昌河北斗星X5 | B48: 48950 | C48: 2025 | E48: 2024 | G48: 2020 | I48: 2022 | K48: 2026 | M48: 2023 | O48: 2020 | Q48: 2019 | S48: 2019 | U48: Post 2030
A50: Suzuki Beidou Star 铃木北斗星 | B50: 42900 | C50: 2026 | E50: 2026 | G50: 2022 | I50: 2023 | K50: 2028 | M50: 2025 | O50: 2022 | Q50: 2022 | S50: 2020 | U50: Post 2030
A52: SGMW Hongguang 上汽五菱宏光 | B52: 49175 | C52: 2025 | E52: 2024 | G52: 2020 | I52: 2022 | K52: 2026 | M52: 2023 | O52: 2020 | Q52: 2019 | S52: 2019 | U52: Post 2030
A54: SGMW Zhiguang 上汽五菱之光 | B54: 35800 | C54: 2029 | E54: 2029 | G54: 2024 | I54: 2025 | K54: Post 2030 | M54: 2027 | O54: 2024 | Q54: 2023 | S54: 2022 | U54: Post 2030
A56: SGMW Lechi 上汽通用乐驰 | B56: 44800 | C56: 2026 | E56: 2025 | G56: 2021 | I56: 2023 | K56: 2027 | M56: 2024 | O56: 2021 | Q56: 2020 | S56: 2019 | U56: Post 2030
A58: Changan Benben 长安奔奔 | B58: 48250 | C58: 2025 | E58: 2024 | G58: 2020 | I58: 2022 | K58: 2026 | M58: 2023 | O58: 2020 | Q58: 2020 | S58: 2019 | U58: Post 2030
...

Sheet A
C4: BAIC EU5
D5: 2019 | E5: 2020 | F5: 2021 | G5: 2022 | H5: 2023 | I5: 2024 | J5: 2025 | K5: 2026 | L5: 2027 | M5: 2028 | N5: 2029 | O5: 2030
C6: Retail Price | D6: 132900 | E6: =D6-((D16-E16)+(D17-E17)+(D18-E18)) -> 123376 | F6: =E6-((E16-F16)+(E17-F17)+(E18-F18)) -> 114784.4 | G6: =F6-((F16-G16)+(F17-G17)+(F18-G18)) -> 107031.96 | H6: =G6-((G16-H16)+(G17-H17)+(G18-H18)) -> 100034.76 | I6: =H6-((H16-I16)+(H17-I17)+(H18-I18)) -> 93717.288 | J6: =I6-((I16-J16)+(I17-J17)+(I18-J18)) -> 88011.559 | K6: =J6-((J16-K16)+(J17-K17)+(J18-K18)) -> 82856.403 | L6: =K6-((K16-L16)+(K17-L17)+(K18-L18)) -> 78196.763 | ... O6: =N6-((N16-O16)+(N17-O17)+(N18-O18)) -> 66719.7
C7: Purchase Tax | D7: 0 | E7: 0 | F7: =F6*0.1 -> 11478.44 | G7: =G6*0.1 -> 10703.196 | H7: =H6*0.1 -> 10003.476 | I7: =I6*0.1 -> 9371.7288 | J7: =J6*0.1 -> 8801.1559 | K7: =K6*0.1 -> 8285.6403 | L7: =L6*0.1 -> 7819.6763 | M7: =M6*0.1 -> 7398.3086 | ... O7: =O6*0.1 -> 6671.97
C8: Consumer Final Price | D8: =D6+D7 -> 132900 | E8: =E6+E7 -> 123376 | F8: =F6+F7 -> 126262.84 | G8: =G6+G7 -> 117735.16 | H8: =H6+H7 -> 110038.24 | I8: =I6+I7 -> 103089.02 | J8: =J6+J7 -> 96812.715 | K8: =K6+K7 -> 91142.043 | ... O8: =O6+O7 -> 73391.67
C9: Dealer Gross Profit(5%) | D9: =D6*0.05 -> 6645 | E9: =E6*0.05 -> 6168.8 | F9: =F6*0.05 -> 5739.22 | G9: =G6*0.05 -> 5351.598 | H9: =H6*0.05 -> 5001.7382 | I9: =I6*0.05 -> 4685.8644 | J9: =J6*0.05 -> 4400.5779 | K9: =K6*0.05 -> 4142.8201 | ... O9: =O6*0.05 -> 3335.985
C10: Range (km) | D10: 450 | E10: 450 | F10: 450 | G10: 450 | H10: 450 | I10: 450 | J10: 450 | K10: 450 | L10: 450 | M10: 450 | N10: 450 | O10: 450
C11: Battery (kwh) | D11: 60.2 | E11: 60.2 | F11: 60.2 | G11: 60.2 | H11: 60.2 | I11: 60.2 | J11: 60.2 | K11: 60.2 | L11: 60.2 | M11: 60.2 | N11: 60.2 | O11: 60.2
C12: Battery Price/wh | D12: 1.2 | E12: =D12*0.9 -> 1.08 | F12: =E12*0.9 -> 0.972 | G12: =F12*0.9 -> 0.8748 | H12: =G12*0.9 -> 0.78732 | I12: =H12*0.9 -> 0.708588 | J12: =I12*0.9 -> 0.6377292 | K12: =J12*0.9 -> 0.57395628 | L12: =K12*0.9 -> 0.51656065 | ... O12: =N12*0.9 -> 0.37657272
C13: Subsidies | D13: 34000 | E13: 35000 | F13: 0 | G13: 0 | H13: 0 | I13: 0 | J13: 0 | K13: 0 | L13: 0 | M13: 0 | N13: 0 | O13: 0
C14: Auto Company Revenue | D14: =D6-D9+D13 -> 160255 | E14: =E6-E9+E13 -> 152207.2 | F14: =F6-F9+F13 -> 109045.18 | G14: =G6-G9+G13 -> 101680.36 | H14: =H6-H9+H13 -> 95033.026 | I14: =I6-I9+I13 -> 89031.423 | J14: =J6-J9+J13 -> 83610.981 | K14: =K6-K9+K13 -> 78713.583 | ... O14: =O6-O9+O13 -> 63383.715
C15: Revenue (after vat) | D15: =D14*0.87 -> 139421.85 | E15: =E14*0.87 -> 132420.26 | F15: =F14*0.87 -> 94869.307 | G15: =G14*0.87 -> 88461.915 | H15: =H14*0.87 -> 82678.732 | I15: =I14*0.87 -> 77457.338 | J15: =J14*0.87 -> 72741.553 | K15: =K14*0.87 -> 68480.817 | ... O15: =O14*0.87 -> 55143.832
C16: Power Battery System Cost | D16: =D12*1000*D11 -> 72240 | E16: =E12*1000*E11 -> 65016 | F16: =F12*1000*F11 -> 58514.4 | G16: =G12*1000*G11 -> 52662.96 | H16: =H12*1000*H11 -> 47396.664 | I16: =I12*1000*I11 -> 42656.998 | J16: =J12*1000*J11 -> 38391.298 | K16: =K12*1000*K11 -> 34552.168 | ... O16: =O12*1000*O11 -> 22669.677
C17: Electric Motor & Electric Controlling | D17: 10000 | E17: =D17-200 -> 9800 | F17: =E17-200 -> 9600 | G17: =F17-200 -> 9400 | H17: =G17-200 -> 9200 | I17: =H17-200 -> 9000 | J17: =I17-200 -> 8800 | K17: =J17-200 -> 8600 | L17: =K17-200 -> 8400 | ... O17: =N17-200 -> 7800
C18: Other Cost | D18: 21000 | E18: =D18*0.9 -> 18900 | F18: =E18*0.9 -> 17010 | G18: =F18*0.9 -> 15309 | H18: =G18*0.9 -> 13778.1 | I18: =H18*0.9 -> 12400.29 | J18: =I18*0.9 -> 11160.261 | K18: =J18*0.9 -> 10044.235 | L18: =K18*0.9 -> 9039.8114 | ... O18: =N18*0.9 -> 6590.0225
C19: Profit Margin(BEV) | D19: =D15-D16-D17-D18 -> 36181.85 | E19: =E15-E16-E17-E18 -> 38704.264 | F19: =F15-F16-F17-F18 -> 9744.9066 | G19: =G15-G16-G17-G18 -> 11089.955 | H19: =H15-H16-H17-H18 -> 12303.968 | I19: =I15-I16-I17-I18 -> 13400.051 | J19: =J15-J16-J17-J18 -> 14389.995 | K19: =K15-K16-K17-K18 -> 15284.414 | ... O19: =O15-O16-O17-O18 -> 18084.132
C20: PM/Revenue | D20: =D19/D14 -> 0.22577673 | E20: =E19/E14 -> 0.25428668 | F20: =F19/F14 -> 0.089365771 | G20: =G19/G14 -> 0.10906683 | H20: =H19/H14 -> 0.12947045 | I20: =I19/I14 -> 0.15050923 | J20: =J19/J14 -> 0.17210652 | K20: =K19/K14 -> 0.19417759 | ... O20: =O19/O14 -> 0.28531196
C21: BAIC D50
D22: 2019 | E22: 2020 | F22: 2021 | G22: 2022 | H22: 2023 | I22: 2024 | J22: 2025 | K22: 2026 | L22: 2027 | M22: 2028 | N22: 2029 | O22: 2030
C23: Retail Price | D23: 99900 | E23: =D23+(E29-D29)+(E30-D30) -> 100360 | F23: =E23+(F29-E29)+(F30-E30) -> 100829.2 | G23: =F23+(G29-F29)+(G30-F30) -> 101307.78 | H23: =G23+(H29-G29)+(H30-G30) -> 101795.94 | I23: =H23+(I29-H29)+(I30-H30) -> 102293.86 | J23: =I23+(J29-I29)+(J30-I30) -> 102801.74 | K23: =J23+(K29-J29)+(K30-J30) -> 103319.77 | L23: =K23+(L29-K29)+(L30-K30) -> 103848.17 | ... O23: =N23+(O29-N29)+(O30-N30) -> 105497.61
C24: Purchase Tax | D24: =D23*0.1 -> 9990 | E24: =E23*0.1 -> 10036 | F24: =F23*0.1 -> 10082.92 | G24: =G23*0.1 -> 10130.778 | H24: =H23*0.1 -> 10179.594 | I24: =I23*0.1 -> 10229.386 | J24: =J23*0.1 -> 10280.174 | K24: =K23*0.1 -> 10331.977 | ... O24: =O23*0.1 -> 10549.761
C25: Consumer Final Price | D25: =D23+D24 -> 109890 | E25: =E23+E24 -> 110396 | F25: =F23+F24 -> 110912.12 | G25: =G23+G24 -> 111438.56 | H25: =H23+H24 -> 111975.53 | I25: =I23+I24 -> 112523.24 | J25: =J23+J24 -> 113081.91 | K25: =K23+K24 -> 113651.75 | ... O25: =O23+O24 -> 116047.37
C26: Dealer Gross Profit (5%) | D26: =D23*0.05 -> 4995 | E26: =E23*0.05 -> 5018 | F26: =F23*0.05 -> 5041.46 | G26: =G23*0.05 -> 5065.3892 | H26: =H23*0.05 -> 5089.797 | I26: =I23*0.05 -> 5114.6929 | J26: =J23*0.05 -> 5140.0868 | K26: =K23*0.05 -> 5165.9885 | ... O26: =O23*0.05 -> 5274.8805
C27: Auto Company Revenue | D27: =D23-D26 -> 94905 | E27: =E23-E26 -> 95342 | F27: =F23-F26 -> 95787.74 | G27: =G23-G26 -> 96242.395 | H27: =H23-H26 -> 96706.143 | I27: =I23-I26 -> 97179.166 | J27: =J23-J26 -> 97661.649 | K27: =K23-K26 -> 98153.782 | ... O27: =O23-O26 -> 100222.73
C28: Revenue (after vat) | D28: =D27*0.87 -> 82567.35 | E28: =E27*0.87 -> 82947.54 | F28: =F27*0.87 -> 83335.334 | G28: =G27*0.87 -> 83730.883 | H28: =H27*0.87 -> 84134.344 | I28: =I27*0.87 -> 84545.874 | J28: =J27*0.87 -> 84965.635 | K28: =K27*0.87 -> 85393.79 | ... O28: =O27*0.87 -> 87193.774
C29: Motor Cost | D29: 15000 | E29: =D29*1.02 -> 15300 | F29: =E29*1.02 -> 15606 | G29: =F29*1.02 -> 15918.12 | H29: =G29*1.02 -> 16236.482 | I29: =H29*1.02 -> 16561.212 | J29: =I29*1.02 -> 16892.436 | K29: =J29*1.02 -> 17230.285 | L29: =K29*1.02 -> 17574.891 | ... O29: =N29*1.02 -> 18650.615
C30: Transmission Cost | D30: 8000 | E30: =D30*1.02 -> 8160 | F30: =E30*1.02 -> 8323.2 | G30: =F30*1.02 -> 8489.664 | H30: =G30*1.02 -> 8659.4573 | I30: =H30*1.02 -> 8832.6464 | J30: =I30*1.02 -> 9009.2994 | K30: =J30*1.02 -> 9189.4853 | L30: =K30*1.02 -> 9373.275 | ... O30: =N30*1.02 -> 9946.9945
C31: 48V System Cost | D31: 4000 | E31: 4000 | F31: 4000 | G31: 4000 | H31: 4000 | I31: 4000 | J31: 4000 | K31: 4000 | L31: 4000 | M31: 4000 | N31: 4000 | O31: 4000
C32: Other Cost | D32: 32000 | E32: 32000 | F32: 32000 | G32: 32000 | H32: 32000 | I32: 32000 | J32: 32000 | K32: 32000 | L32: 32000 | M32: 32000 | N32: 32000 | O32: 32000
C33: Profit Margin(ICEV) | D33: =D28-D29-D30-D31-D32 -> 23567.35 | E33: =E28-E29-E30-E31-E32 -> 23487.54 | F33: =F28-F29-F30-F31-F32 -> 23406.134 | G33: =G28-G29-G30-G31-G32 -> 23323.099 | H33: =H28-H29-H30-H31-H32 -> 23238.404 | I33: =I28-I29-I30-I31-I32 -> 23152.016 | J33: =J28-J29-J30-J31-J32 -> 23063.899 | K33: =K28-K29-K30-K31-K32 -> 22974.02 | ... O33: =O28-O29-O30-O31-O32 -> 22596.165
C34: PM/Revenue | D34: =D33/D27 -> 0.24832569 | E34: =E33/E27 -> 0.2463504 | F34: =F33/F27 -> 0.24435417 | G34: =G33/G27 -> 0.24233706 | H34: =H33/H27 -> 0.24029916 | I34: =I33/I27 -> 0.23824053 | J34: =J33/J27 -> 0.23616127 | K34: =K33/K27 -> 0.23406148 | ... O34: =O33/O27 -> 0.22545949
D37: =D8-D25 -> 23010 | E37: =E8-E25 -> 12980 | F37: =F8-F25 -> 15350.72 | G37: =G8-G25 -> 6296.5936 | H37: =H8-H25 -> -1937.2932 | I37: =I8-I25 -> -9434.228 | J37: =J8-J25 -> -16269.194 | K37: =K8-K25 -> -22509.704 | ... O37: =O8-O25 -> -42655.7

Sheet A class comparison
C4: BAIC EU5
D5: 2019 | E5: 2020 | F5: 2021 | G5: 2022 | H5: 2023 | I5: 2024 | J5: 2025 | K5: 2026 | L5: 2027 | M5: 2028 | N5: 2029 | O5: 2030
C6: Retail Price | D6: 182800 | E6: =D6-((D16-E16)+(D17-E17)+(D18-E18)) -> 173276 | F6: =E6-((E16-F16)+(E17-F17)+(E18-F18)) -> 164684.4 | G6: =F6-((F16-G16)+(F17-G17)+(F18-G18)) -> 156931.96 | H6: =G6-((G16-H16)+(G17-H17)+(G18-H18)) -> 149934.76 | I6: =H6-((H16-I16)+(H17-I17)+(H18-I18)) -> 143617.29 | J6: =I6-((I16-J16)+(I17-J17)+(I18-J18)) -> 137911.56 | K6: =J6-((J16-K16)+(J17-K17)+(J18-K18)) -> 132756.4 | L6: =K6-((K16-L16)+(K17-L17)+(K18-L18)) -> 128096.76 | ... O6: =N6-((N16-O16)+(N17-O17)+(N18-O18)) -> 116619.7
C7: Purchase Tax | D7: 0 | E7: 0 | F7: =F6*0.1 -> 16468.44 | G7: =G6*0.1 -> 15693.196 | H7: =H6*0.1 -> 14993.476 | I7: =I6*0.1 -> 14361.729 | J7: =J6*0.1 -> 13791.156 | K7: =K6*0.1 -> 13275.64 | L7: =L6*0.1 -> 12809.676 | M7: =M6*0.1 -> 12388.309 | ... O7: =O6*0.1 -> 11661.97
C8: Consumer Final Price | D8: =D6+D7 -> 182800 | E8: =E6+E7 -> 173276 | F8: =F6+F7 -> 181152.84 | G8: =G6+G7 -> 172625.16 | H8: =H6+H7 -> 164928.24 | I8: =I6+I7 -> 157979.02 | J8: =J6+J7 -> 151702.71 | K8: =K6+K7 -> 146032.04 | ... O8: =O6+O7 -> 128281.67
C9: Dealer Gross Profit(5%) | D9: =D6*0.05 -> 9140 | E9: =E6*0.05 -> 8663.8 | F9: =F6*0.05 -> 8234.22 | G9: =G6*0.05 -> 7846.598 | H9: =H6*0.05 -> 7496.7382 | I9: =I6*0.05 -> 7180.8644 | J9: =J6*0.05 -> 6895.5779 | K9: =K6*0.05 -> 6637.8201 | ... O9: =O6*0.05 -> 5830.985
C10: Range (km) | D10: 450 | E10: 450 | F10: 450 | G10: 450 | H10: 450 | I10: 450 | J10: 450 | K10: 450 | L10: 450 | M10: 450 | N10: 450 | O10: 450
C11: Battery (kwh) | D11: 60.2 | E11: 60.2 | F11: 60.2 | G11: 60.2 | H11: 60.2 | I11: 60.2 | J11: 60.2 | K11: 60.2 | L11: 60.2 | M11: 60.2 | N11: 60.2 | O11: 60.2
C12: Battery Price/wh | D12: 1.2 | E12: =D12*0.9 -> 1.08 | F12: =E12*0.9 -> 0.972 | G12: =F12*0.9 -> 0.8748 | H12: =G12*0.9 -> 0.78732 | I12: =H12*0.9 -> 0.708588 | J12: =I12*0.9 -> 0.6377292 | K12: =J12*0.9 -> 0.57395628 | L12: =K12*0.9 -> 0.51656065 | ... O12: =N12*0.9 -> 0.37657272
C13: Subsidies | D13: 34000 | E13: 35000 | F13: 0 | G13: 0 | H13: 0 | I13: 0 | J13: 0 | K13: 0 | L13: 0 | M13: 0 | N13: 0 | O13: 0
C14: Auto Company Revenue | D14: =D6-D9+D13 -> 207660 | E14: =E6-E9+E13 -> 199612.2 | F14: =F6-F9+F13 -> 156450.18 | G14: =G6-G9+G13 -> 149085.36 | H14: =H6-H9+H13 -> 142438.03 | I14: =I6-I9+I13 -> 136436.42 | J14: =J6-J9+J13 -> 131015.98 | K14: =K6-K9+K13 -> 126118.58 | ... O14: =O6-O9+O13 -> 110788.71
C15: Revenue (after vat) | D15: =D14*0.87 -> 180664.2 | E15: =E14*0.87 -> 173662.61 | F15: =F14*0.87 -> 136111.66 | G15: =G14*0.87 -> 129704.26 | H15: =H14*0.87 -> 123921.08 | I15: =I14*0.87 -> 118699.69 | J15: =J14*0.87 -> 113983.9 | K15: =K14*0.87 -> 109723.17 | ... O15: =O14*0.87 -> 96386.182
C16: Power Battery System Cost | D16: =D12*1000*D11 -> 72240 | E16: =E12*1000*E11 -> 65016 | F16: =F12*1000*F11 -> 58514.4 | G16: =G12*1000*G11 -> 52662.96 | H16: =H12*1000*H11 -> 47396.664 | I16: =I12*1000*I11 -> 42656.998 | J16: =J12*1000*J11 -> 38391.298 | K16: =K12*1000*K11 -> 34552.168 | ... O16: =O12*1000*O11 -> 22669.677
C17: Electric Motor & Electric Controlling | D17: 10000 | E17: =D17-200 -> 9800 | F17: =E17-200 -> 9600 | G17: =F17-200 -> 9400 | H17: =G17-200 -> 9200 | I17: =H17-200 -> 9000 | J17: =I17-200 -> 8800 | K17: =J17-200 -> 8600 | L17: =K17-200 -> 8400 | ... O17: =N17-200 -> 7800
C18: Other Cost | D18: 21000 | E18: =D18*0.9 -> 18900 | F18: =E18*0.9 -> 17010 | G18: =F18*0.9 -> 15309 | H18: =G18*0.9 -> 13778.1 | I18: =H18*0.9 -> 12400.29 | J18: =I18*0.9 -> 11160.261 | K18: =J18*0.9 -> 10044.235 | L18: =K18*0.9 -> 9039.8114 | ... O18: =N18*0.9 -> 6590.0225
C19: Profit Margin(BEV) | D19: =D15-D16-D17-D18 -> 77424.2 | E19: =E15-E16-E17-E18 -> 79946.614 | F19: =F15-F16-F17-F18 -> 50987.257 | G19: =G15-G16-G17-G18 -> 52332.305 | H19: =H15-H16-H17-H18 -> 53546.318 | I19: =I15-I16-I17-I18 -> 54642.401 | J19: =J15-J16-J17-J18 -> 55632.345 | K19: =K15-K16-K17-K18 -> 56526.764 | ... O19: =O15-O16-O17-O18 -> 59326.482
C20: PM/Revenue | D20: =D19/D14 -> 0.37284118 | E20: =E19/E14 -> 0.40050966 | F20: =F19/F14 -> 0.32590091 | G20: =G19/G14 -> 0.35102242 | H20: =H19/H14 -> 0.37592713 | I20: =I19/I14 -> 0.40049716 | J20: =J19/J14 -> 0.42462259 | K20: =K19/K14 -> 0.44820329 | ... O20: =O19/O14 -> 0.5354921
C21: BAIC D50
D22: 2019 | E22: 2020 | F22: 2021 | G22: 2022 | H22: 2023 | I22: 2024 | J22: 2025 | K22: 2026 | L22: 2027 | M22: 2028 | N22: 2029 | O22: 2030
C23: Retail Price | D23: 131400 | E23: =D23+(E29-D29)+(E30-D30) -> 131860 | F23: =E23+(F29-E29)+(F30-E30) -> 132329.2 | G23: =F23+(G29-F29)+(G30-F30) -> 132807.78 | H23: =G23+(H29-G29)+(H30-G30) -> 133295.94 | I23: =H23+(I29-H29)+(I30-H30) -> 133793.86 | J23: =I23+(J29-I29)+(J30-I30) -> 134301.74 | K23: =J23+(K29-J29)+(K30-J30) -> 134819.77 | L23: =K23+(L29-K29)+(L30-K30) -> 135348.17 | ... O23: =N23+(O29-N29)+(O30-N30) -> 136997.61
C24: Purchase Tax | D24: =D23*0.1 -> 13140 | E24: =E23*0.1 -> 13186 | F24: =F23*0.1 -> 13232.92 | G24: =G23*0.1 -> 13280.778 | H24: =H23*0.1 -> 13329.594 | I24: =I23*0.1 -> 13379.386 | J24: =J23*0.1 -> 13430.174 | K24: =K23*0.1 -> 13481.977 | ... O24: =O23*0.1 -> 13699.761
C25: Consumer Final Price | D25: =D23+D24 -> 144540 | E25: =E23+E24 -> 145046 | F25: =F23+F24 -> 145562.12 | G25: =G23+G24 -> 146088.56 | H25: =H23+H24 -> 146625.53 | I25: =I23+I24 -> 147173.24 | J25: =J23+J24 -> 147731.91 | K25: =K23+K24 -> 148301.75 | ... O25: =O23+O24 -> 150697.37
C26: Dealer Gross Profit (5%) | D26: =D23*0.05 -> 6570 | E26: =E23*0.05 -> 6593 | F26: =F23*0.05 -> 6616.46 | G26: =G23*0.05 -> 6640.3892 | H26: =H23*0.05 -> 6664.797 | I26: =I23*0.05 -> 6689.6929 | J26: =J23*0.05 -> 6715.0868 | K26: =K23*0.05 -> 6740.9885 | ... O26: =O23*0.05 -> 6849.8805
C27: Auto Company Revenue | D27: =D23-D26 -> 124830 | E27: =E23-E26 -> 125267 | F27: =F23-F26 -> 125712.74 | G27: =G23-G26 -> 126167.39 | H27: =H23-H26 -> 126631.14 | I27: =I23-I26 -> 127104.17 | J27: =J23-J26 -> 127586.65 | K27: =K23-K26 -> 128078.78 | ... O27: =O23-O26 -> 130147.73
C28: Revenue (after vat) | D28: =D27*0.87 -> 108602.1 | E28: =E27*0.87 -> 108982.29 | F28: =F27*0.87 -> 109370.08 | G28: =G27*0.87 -> 109765.63 | H28: =H27*0.87 -> 110169.09 | I28: =I27*0.87 -> 110580.62 | J28: =J27*0.87 -> 111000.38 | K28: =K27*0.87 -> 111428.54 | ... O28: =O27*0.87 -> 113228.52
C29: Motor Cost | D29: 15000 | E29: =D29*1.02 -> 15300 | F29: =E29*1.02 -> 15606 | G29: =F29*1.02 -> 15918.12 | H29: =G29*1.02 -> 16236.482 | I29: =H29*1.02 -> 16561.212 | J29: =I29*1.02 -> 16892.436 | K29: =J29*1.02 -> 17230.285 | L29: =K29*1.02 -> 17574.891 | ... O29: =N29*1.02 -> 18650.615
C30: Transmission Cost | D30: 8000 | E30: =D30*1.02 -> 8160 | F30: =E30*1.02 -> 8323.2 | G30: =F30*1.02 -> 8489.664 | H30: =G30*1.02 -> 8659.4573 | I30: =H30*1.02 -> 8832.6464 | J30: =I30*1.02 -> 9009.2994 | K30: =J30*1.02 -> 9189.4853 | L30: =K30*1.02 -> 9373.275 | ... O30: =N30*1.02 -> 9946.9945
C31: 48V System Cost | D31: 4000 | E31: 4000 | F31: 4000 | G31: 4000 | H31: 4000 | I31: 4000 | J31: 4000 | K31: 4000 | L31: 4000 | M31: 4000 | N31: 4000 | O31: 4000
C32: Other Cost | D32: 32000 | E32: 32000 | F32: 32000 | G32: 32000 | H32: 32000 | I32: 32000 | J32: 32000 | K32: 32000 | L32: 32000 | M32: 32000 | N32: 32000 | O32: 32000
C33: Profit Margin(ICEV) | D33: =D28-D29-D30-D31-D32 -> 49602.1 | E33: =E28-E29-E30-E31-E32 -> 49522.29 | F33: =F28-F29-F30-F31-F32 -> 49440.884 | G33: =G28-G29-G30-G31-G32 -> 49357.849 | H33: =H28-H29-H30-H31-H32 -> 49273.154 | I33: =I28-I29-I30-I31-I32 -> 49186.766 | J33: =J28-J29-J30-J31-J32 -> 49098.649 | K33: =K28-K29-K30-K31-K32 -> 49008.77 | ... O33: =O28-O29-O30-O31-O32 -> 48630.915
C34: PM/Revenue | D34: =D33/D27 -> 0.39735721 | E34: =E33/E27 -> 0.39533389 | F34: =F33/F27 -> 0.39328459 | G34: =G33/G27 -> 0.39120923 | H34: =H33/H27 -> 0.38910771 | I34: =I33/I27 -> 0.38697997 | J34: =J33/J27 -> 0.38482591 | K34: =K33/K27 -> 0.3826455 | ... O34: =O33/O27 -> 0.37365934
D36: 2019 | E36: 2020 | F36: 2021 | G36: 2022 | H36: 2023 | I36: 2024 | J36: 2025 | K36: 2026 | L36: 2027 | M36: 2028 | N36: 2029 | O36: 2030
D37: =D8-D25 -> 38260 | E37: =E8-E25 -> 28230 | F37: =F8-F25 -> 35590.72 | G37: =G8-G25 -> 26536.594 | H37: =H8-H25 -> 18302.707 | I37: =I8-I25 -> 10805.772 | J37: =J8-J25 -> 3970.8055 | K37: =K8-K25 -> -2269.7041 | ... O37: =O8-O25 -> -22415.7
B40: ICEV BEV | D40: BAIC EU 5 北汽EU5 | F40: JAC iEV7L 江淮iEV7L | H40: Roewe ei5 荣威ei5 | J40: GAC NE Aion S 广汽新能源AionS | L40: BYD Yuan EV360（SUV） 比亚迪 元 EV360 | N40: BYD Yuan EV（SUV） 比亚迪 元 EV | P40: BMW i3 宝马i3 | Q40: Volkswagen e-Golf 大众e高尔夫 | S40: Volkswagen e-Bora 大众e宝来 | U40: Hyundai ENCINO（SUV） 现代昂希诺纯电 | W40: Honda VE-1（SUV） 本田VE-1纯电 | Y40: Honda XNV（SUV） 本田XNV | AA40: Buick Velite 6 别克微蓝6
D41: 152400 | F41: 109150 | H41: 143800 | J41: 173300 | L41: 117900 | N41: 144350 | P41: 305800 | Q41: 158250 | S41: 141800 | U41: 207550 | W41: 169800 | Y41: 174800 | AA41: 182800 | AD41: =_xlfn.STDEV.P(D41,H41,J41,N41,Q41,S41,W41,Y41,AA41) -> 14571.842
B42: BAIC D50 北汽绅宝D50 | C42: 84900 | D42: 2029 | F42: 2022 | H42: 2028 | J42: Post 2030 | L42: 2023 | N42: 2028 | P42: Post 2030 | Q42: Post 2030 | S42: 2027 | U42: Post 2030 | W42: Post 2030 | Y42: Post 2030 | AA42: Post 2030
B44: JAC Heyue A30 江淮和悦A30 | C44: 62900 | D44: Post 2030 | F44: 2025 | H44: Post 2030 | J44: Post 2030 | L44: 2027 | N44: Post 2030 | P44: Post 2030 | Q44: Post 2030 | S44: Post 2030 | U44: Post 2030 | W44: Post 2030 | Y44: Post 2030 | AA44: Post 2030
B46: Roewe i5GL 荣威i5GL | C46: 107900 | D46: 2025 | F46: 2019 | H46: 2024 | J46: 2029 | L46: 2019 | N46: 2024 | P46: Post 2030 | Q46: 2026 | S46: 2023 | U46: Post 2030 | W46: 2028 | Y46: 2029 | AA46: Post 2030
B48: Roewe i6 Plus 荣威i6 Plus | C48: 114800 | D48: 2024 | F48: 2019 | H48: 2023 | J48: 2027 | L48: 2019 | N48: 2023 | P48: Post 2030 | Q48: 2025 | S48: 2022 | U48: Post 2030 | W48: 2027 | Y48: 2028 | AA48: 2030
B50: BYD Tang （SUV） 比亚迪唐 | C50: 149900 | D50: 2019 | F50: 2019 | H50: 2019 | J50: 2020 | L50: 2019 | N50: 2019 | P50: Post 2030 | Q50: 2019 | S50: 2019 | U50: 2027 | W50: 2020 | Y50: 2020 | AA50: 2023
...

Sheet B
C4: BYD Qin Pro EV
D5: 2019 | E5: 2020 | F5: 2021 | G5: 2022 | H5: 2023 | I5: 2024 | J5: 2025 | K5: 2026 | L5: 2027 | M5: 2028 | N5: 2029 | O5: 2030
C6: Retail Price | D6: 174800 | E6: =D6-((D16-E16)+(D17-E17)+(D18-E18)) -> 162760 | F6: =E6-((E16-F16)+(E17-F17)+(E18-F18)) -> 151904 | G6: =F6-((F16-G16)+(F17-G17)+(F18-G18)) -> 142113.6 | H6: =G6-((G16-H16)+(G17-H17)+(G18-H18)) -> 133282.24 | I6: =H6-((H16-I16)+(H17-I17)+(H18-I18)) -> 125314.02 | J6: =I6-((I16-J16)+(I17-J17)+(I18-J18)) -> 118122.61 | K6: =J6-((J16-K16)+(J17-K17)+(J18-K18)) -> 111630.35 | L6: =K6-((K16-L16)+(K17-L17)+(K18-L18)) -> 105767.32 | ... O6: =N6-((N16-O16)+(N17-O17)+(N18-O18)) -> 91355.175
C7: Purchase Tax | D7: 0 | E7: 0 | F7: =F6*0.1 -> 15190.4 | G7: =G6*0.1 -> 14211.36 | H7: =H6*0.1 -> 13328.224 | I7: =I6*0.1 -> 12531.402 | J7: =J6*0.1 -> 11812.261 | K7: =K6*0.1 -> 11163.035 | L7: =L6*0.1 -> 10576.732 | M7: =M6*0.1 -> 10047.059 | ... O7: =O6*0.1 -> 9135.5175
C8: Consumer Final Price | D8: =D6+D7 -> 174800 | E8: =E6+E7 -> 162760 | F8: =F6+F7 -> 167094.4 | G8: =G6+G7 -> 156324.96 | H8: =H6+H7 -> 146610.46 | I8: =I6+I7 -> 137845.42 | J8: =J6+J7 -> 129934.88 | K8: =K6+K7 -> 122793.39 | ... O8: =O6+O7 -> 100490.69
C9: Dealer Gross Profit(5%) | D9: =D6*0.05 -> 8740 | E9: =E6*0.05 -> 8138 | F9: =F6*0.05 -> 7595.2 | G9: =G6*0.05 -> 7105.68 | H9: =H6*0.05 -> 6664.112 | I9: =I6*0.05 -> 6265.7008 | J9: =J6*0.05 -> 5906.1307 | K9: =K6*0.05 -> 5581.5176 | ... O9: =O6*0.05 -> 4567.7587
C10: Range (km) | D10: 420 | E10: 420 | F10: 420 | G10: 420 | H10: 420 | I10: 420 | J10: 420 | K10: 420 | L10: 420 | M10: 420 | N10: 420 | O10: 420
C11: Battery (kwh) | D11: 69.5 | E11: 69.5 | F11: 69.5 | G11: 69.5 | H11: 69.5 | I11: 69.5 | J11: 69.5 | K11: 69.5 | L11: 69.5 | M11: 69.5 | N11: 69.5 | O11: 69.5
C12: Battery Price/wh | D12: 1.2 | E12: =D12*0.9 -> 1.08 | F12: =E12*0.9 -> 0.972 | G12: =F12*0.9 -> 0.8748 | H12: =G12*0.9 -> 0.78732 | I12: =H12*0.9 -> 0.708588 | J12: =I12*0.9 -> 0.6377292 | K12: =J12*0.9 -> 0.57395628 | L12: =K12*0.9 -> 0.51656065 | ... O12: =N12*0.9 -> 0.37657272
C13: Subsidies | D13: 35000 | E13: 35000 | F13: 0 | G13: 0 | H13: 0 | I13: 0 | J13: 0 | K13: 0 | L13: 0 | M13: 0 | N13: 0 | O13: 0
C14: Auto Company Revenue | D14: =D6-D9+D13 -> 201060 | E14: =E6-E9+E13 -> 189622 | F14: =F6-F9+F13 -> 144308.8 | G14: =G6-G9+G13 -> 135007.92 | H14: =H6-H9+H13 -> 126618.13 | I14: =I6-I9+I13 -> 119048.32 | J14: =J6-J9+J13 -> 112216.48 | K14: =K6-K9+K13 -> 106048.84 | ... O14: =O6-O9+O13 -> 86787.416
C15: Revenue (after vat) | D15: =D14*0.87 -> 174922.2 | E15: =E14*0.87 -> 164971.14 | F15: =F14*0.87 -> 125548.66 | G15: =G14*0.87 -> 117456.89 | H15: =H14*0.87 -> 110157.77 | I15: =I14*0.87 -> 103572.03 | J15: =J14*0.87 -> 97628.341 | K15: =K14*0.87 -> 92262.487 | ... O15: =O14*0.87 -> 75505.052
C16: Power Battery System Cost | D16: =D12*1000*D11 -> 83400 | E16: =E12*1000*E11 -> 75060 | F16: =F12*1000*F11 -> 67554 | G16: =G12*1000*G11 -> 60798.6 | H16: =H12*1000*H11 -> 54718.74 | I16: =I12*1000*I11 -> 49246.866 | J16: =J12*1000*J11 -> 44322.179 | K16: =K12*1000*K11 -> 39889.961 | ... O16: =O12*1000*O11 -> 26171.804
C17: Electric Motor & Electric Controlling | D17: 15000 | E17: =D17-200 -> 14800 | F17: =E17-200 -> 14600 | G17: =F17-200 -> 14400 | H17: =G17-200 -> 14200 | I17: =H17-200 -> 14000 | J17: =I17-200 -> 13800 | K17: =J17-200 -> 13600 | L17: =K17-200 -> 13400 | ... O17: =N17-200 -> 12800
C18: Other Cost | D18: 35000 | E18: =D18*0.9 -> 31500 | F18: =E18*0.9 -> 28350 | G18: =F18*0.9 -> 25515 | H18: =G18*0.9 -> 22963.5 | I18: =H18*0.9 -> 20667.15 | J18: =I18*0.9 -> 18600.435 | K18: =J18*0.9 -> 16740.392 | L18: =K18*0.9 -> 15066.352 | ... O18: =N18*0.9 -> 10983.371
C19: Profit Margin(BEV) | D19: =D15-D16-D17-D18 -> 41522.2 | E19: =E15-E16-E17-E18 -> 43611.14 | F19: =F15-F16-F17-F18 -> 15044.656 | G19: =G15-G16-G17-G18 -> 16743.29 | H19: =H15-H16-H17-H18 -> 18275.531 | I19: =I15-I16-I17-I18 -> 19658.018 | J19: =J15-J16-J17-J18 -> 20905.726 | K19: =K15-K16-K17-K18 -> 22032.134 | ... O19: =O15-O16-O17-O18 -> 25549.877
C20: PM/Revenue | D20: =D19/D14 -> 0.20651646 | E20: =E19/E14 -> 0.22998987 | F20: =F19/F14 -> 0.10425321 | G20: =G19/G14 -> 0.1240171 | H20: =H19/H14 -> 0.14433582 | I20: =I19/I14 -> 0.16512639 | J20: =J19/J14 -> 0.18629818 | K20: =K19/K14 -> 0.2077546 | ... O20: =O19/O14 -> 0.29439611
C21: BYD Pro
D22: 2019 | E22: 2020 | F22: 2021 | G22: 2022 | H22: 2023 | I22: 2024 | J22: 2025 | K22: 2026 | L22: 2027 | M22: 2028 | N22: 2029 | O22: 2030
C23: Retail Price | D23: 115800 | E23: =D23+(E29-D29)+(E30-D30) -> 116400 | F23: =E23+(F29-E29)+(F30-E30) -> 117012 | G23: =F23+(G29-F29)+(G30-F30) -> 117636.24 | H23: =G23+(H29-G29)+(H30-G30) -> 118272.96 | I23: =H23+(I29-H29)+(I30-H30) -> 118922.42 | J23: =I23+(J29-I29)+(J30-I30) -> 119584.87 | K23: =J23+(K29-J29)+(K30-J30) -> 120260.57 | L23: =K23+(L29-K29)+(L30-K30) -> 120949.78 | ... O23: =N23+(O29-N29)+(O30-N30) -> 123101.23
C24: Purchase Tax | D24: =D23*0.1 -> 11580 | E24: =E23*0.1 -> 11640 | F24: =F23*0.1 -> 11701.2 | G24: =G23*0.1 -> 11763.624 | H24: =H23*0.1 -> 11827.296 | I24: =I23*0.1 -> 11892.242 | J24: =J23*0.1 -> 11958.487 | K24: =K23*0.1 -> 12026.057 | ... O24: =O23*0.1 -> 12310.123
C25: Consumer Final Price | D25: =D23+D24 -> 127380 | E25: =E23+E24 -> 128040 | F25: =F23+F24 -> 128713.2 | G25: =G23+G24 -> 129399.86 | H25: =H23+H24 -> 130100.26 | I25: =I23+I24 -> 130814.67 | J25: =J23+J24 -> 131543.36 | K25: =K23+K24 -> 132286.63 | ... O25: =O23+O24 -> 135411.35
C26: Dealer Gross Profit (5%) | D26: =D23*0.05 -> 5790 | E26: =E23*0.05 -> 5820 | F26: =F23*0.05 -> 5850.6 | G26: =G23*0.05 -> 5881.812 | H26: =H23*0.05 -> 5913.6482 | I26: =I23*0.05 -> 5946.1212 | J26: =J23*0.05 -> 5979.2436 | K26: =K23*0.05 -> 6013.0285 | ... O26: =O23*0.05 -> 6155.0615
C27: Auto Company Revenue | D27: =D23-D26 -> 110010 | E27: =E23-E26 -> 110580 | F27: =F23-F26 -> 111161.4 | G27: =G23-G26 -> 111754.43 | H27: =H23-H26 -> 112359.32 | I27: =I23-I26 -> 112976.3 | J27: =J23-J26 -> 113605.63 | K27: =K23-K26 -> 114247.54 | ... O27: =O23-O26 -> 116946.17
C28: Revenue (after vat) | D28: =D27*0.87 -> 95708.7 | E28: =E27*0.87 -> 96204.6 | F28: =F27*0.87 -> 96710.418 | G28: =G27*0.87 -> 97226.352 | H28: =H27*0.87 -> 97752.605 | I28: =I27*0.87 -> 98289.384 | J28: =J27*0.87 -> 98836.897 | K28: =K27*0.87 -> 99395.361 | ... O28: =O27*0.87 -> 101743.17
C29: Motor Cost | D29: 20000 | E29: =D29*1.02 -> 20400 | F29: =E29*1.02 -> 20808 | G29: =F29*1.02 -> 21224.16 | H29: =G29*1.02 -> 21648.643 | I29: =H29*1.02 -> 22081.616 | J29: =I29*1.02 -> 22523.248 | K29: =J29*1.02 -> 22973.713 | L29: =K29*1.02 -> 23433.188 | ... O29: =N29*1.02 -> 24867.486
C30: Transmission Cost | D30: 10000 | E30: =D30*1.02 -> 10200 | F30: =E30*1.02 -> 10404 | G30: =F30*1.02 -> 10612.08 | H30: =G30*1.02 -> 10824.322 | I30: =H30*1.02 -> 11040.808 | J30: =I30*1.02 -> 11261.624 | K30: =J30*1.02 -> 11486.857 | L30: =K30*1.02 -> 11716.594 | ... O30: =N30*1.02 -> 12433.743
C31: 48V System Cost | D31: 4000 | E31: 4000 | F31: 4000 | G31: 4000 | H31: 4000 | I31: 4000 | J31: 4000 | K31: 4000 | L31: 4000 | M31: 4000 | N31: 4000 | O31: 4000
C32: Other Cost | D32: 40000 | E32: 40000 | F32: 40000 | G32: 40000 | H32: 40000 | I32: 40000 | J32: 40000 | K32: 40000 | L32: 40000 | M32: 40000 | N32: 40000 | O32: 40000
C33: Profit Margin(ICEV) | D33: =D28-D29-D30-D31-D32 -> 21708.7 | E33: =E28-E29-E30-E31-E32 -> 21604.6 | F33: =F28-F29-F30-F31-F32 -> 21498.418 | G33: =G28-G29-G30-G31-G32 -> 21390.112 | H33: =H28-H29-H30-H31-H32 -> 21279.641 | I33: =I28-I29-I30-I31-I32 -> 21166.959 | J33: =J28-J29-J30-J31-J32 -> 21052.025 | K33: =K28-K29-K30-K31-K32 -> 20934.791 | ... O33: =O28-O29-O30-O31-O32 -> 20441.937
C34: PM/Revenue | D34: =D33/D27 -> 0.19733388 | E34: =E33/E27 -> 0.19537529 | F34: =F33/F27 -> 0.19339823 | G34: =G33/G27 -> 0.19140282 | H34: =H33/H27 -> 0.1893892 | I34: =I33/I27 -> 0.18735752 | J34: =J33/J27 -> 0.18530794 | K34: =K33/K27 -> 0.18324063 | ... O34: =O33/O27 -> 0.17479783

Sheet B class comparison
C4: BYD Qin Pro EV
D5: 2019 | E5: 2020 | F5: 2021 | G5: 2022 | H5: 2023 | I5: 2024 | J5: 2025 | K5: 2026 | L5: 2027 | M5: 2028 | N5: 2029 | O5: 2030
C6: Retail Price | D6: 134900 | E6: =D6-((D16-E16)+(D17-E17)+(D18-E18)) -> 122860 | F6: =E6-((E16-F16)+(E17-F17)+(E18-F18)) -> 112004 | G6: =F6-((F16-G16)+(F17-G17)+(F18-G18)) -> 102213.6 | H6: =G6-((G16-H16)+(G17-H17)+(G18-H18)) -> 93382.24 | I6: =H6-((H16-I16)+(H17-I17)+(H18-I18)) -> 85414.016 | J6: =I6-((I16-J16)+(I17-J17)+(I18-J18)) -> 78222.614 | K6: =J6-((J16-K16)+(J17-K17)+(J18-K18)) -> 71730.353 | L6: =K6-((K16-L16)+(K17-L17)+(K18-L18)) -> 65867.318 | ... O6: =N6-((N16-O16)+(N17-O17)+(N18-O18)) -> 51455.175
C7: Purchase Tax | D7: 0 | E7: 0 | F7: =F6*0.1 -> 11200.4 | G7: =G6*0.1 -> 10221.36 | H7: =H6*0.1 -> 9338.224 | I7: =I6*0.1 -> 8541.4016 | J7: =J6*0.1 -> 7822.2614 | K7: =K6*0.1 -> 7173.0353 | L7: =L6*0.1 -> 6586.7318 | M7: =M6*0.1 -> 6057.0586 | ... O7: =O6*0.1 -> 5145.5175
C8: Consumer Final Price | D8: =D6+D7 -> 134900 | E8: =E6+E7 -> 122860 | F8: =F6+F7 -> 123204.4 | G8: =G6+G7 -> 112434.96 | H8: =H6+H7 -> 102720.46 | I8: =I6+I7 -> 93955.418 | J8: =J6+J7 -> 86044.876 | K8: =K6+K7 -> 78903.388 | ... O8: =O6+O7 -> 56600.692
C9: Dealer Gross Profit(5%) | D9: =D6*0.05 -> 6745 | E9: =E6*0.05 -> 6143 | F9: =F6*0.05 -> 5600.2 | G9: =G6*0.05 -> 5110.68 | H9: =H6*0.05 -> 4669.112 | I9: =I6*0.05 -> 4270.7008 | J9: =J6*0.05 -> 3911.1307 | K9: =K6*0.05 -> 3586.5176 | ... O9: =O6*0.05 -> 2572.7587
C10: Range (km) | D10: 420 | E10: 420 | F10: 420 | G10: 420 | H10: 420 | I10: 420 | J10: 420 | K10: 420 | L10: 420 | M10: 420 | N10: 420 | O10: 420
C11: Battery (kwh) | D11: 69.5 | E11: 69.5 | F11: 69.5 | G11: 69.5 | H11: 69.5 | I11: 69.5 | J11: 69.5 | K11: 69.5 | L11: 69.5 | M11: 69.5 | N11: 69.5 | O11: 69.5
C12: Battery Price/wh | D12: 1.2 | E12: =D12*0.9 -> 1.08 | F12: =E12*0.9 -> 0.972 | G12: =F12*0.9 -> 0.8748 | H12: =G12*0.9 -> 0.78732 | I12: =H12*0.9 -> 0.708588 | J12: =I12*0.9 -> 0.6377292 | K12: =J12*0.9 -> 0.57395628 | L12: =K12*0.9 -> 0.51656065 | ... O12: =N12*0.9 -> 0.37657272
C13: Subsidies | D13: 35000 | E13: 35000 | F13: 0 | G13: 0 | H13: 0 | I13: 0 | J13: 0 | K13: 0 | L13: 0 | M13: 0 | N13: 0 | O13: 0
C14: Auto Company Revenue | D14: =D6-D9+D13 -> 163155 | E14: =E6-E9+E13 -> 151717 | F14: =F6-F9+F13 -> 106403.8 | G14: =G6-G9+G13 -> 97102.92 | H14: =H6-H9+H13 -> 88713.128 | I14: =I6-I9+I13 -> 81143.315 | J14: =J6-J9+J13 -> 74311.484 | K14: =K6-K9+K13 -> 68143.835 | ... O14: =O6-O9+O13 -> 48882.416
C15: Revenue (after vat) | D15: =D14*0.87 -> 141944.85 | E15: =E14*0.87 -> 131993.79 | F15: =F14*0.87 -> 92571.306 | G15: =G14*0.87 -> 84479.54 | H15: =H14*0.87 -> 77180.421 | I15: =I14*0.87 -> 70594.684 | J15: =J14*0.87 -> 64650.991 | K15: =K14*0.87 -> 59285.137 | ... O15: =O14*0.87 -> 42527.702
C16: Power Battery System Cost | D16: =D12*1000*D11 -> 83400 | E16: =E12*1000*E11 -> 75060 | F16: =F12*1000*F11 -> 67554 | G16: =G12*1000*G11 -> 60798.6 | H16: =H12*1000*H11 -> 54718.74 | I16: =I12*1000*I11 -> 49246.866 | J16: =J12*1000*J11 -> 44322.179 | K16: =K12*1000*K11 -> 39889.961 | ... O16: =O12*1000*O11 -> 26171.804
C17: Electric Motor & Electric Controlling | D17: 15000 | E17: =D17-200 -> 14800 | F17: =E17-200 -> 14600 | G17: =F17-200 -> 14400 | H17: =G17-200 -> 14200 | I17: =H17-200 -> 14000 | J17: =I17-200 -> 13800 | K17: =J17-200 -> 13600 | L17: =K17-200 -> 13400 | ... O17: =N17-200 -> 12800
C18: Other Cost | D18: 35000 | E18: =D18*0.9 -> 31500 | F18: =E18*0.9 -> 28350 | G18: =F18*0.9 -> 25515 | H18: =G18*0.9 -> 22963.5 | I18: =H18*0.9 -> 20667.15 | J18: =I18*0.9 -> 18600.435 | K18: =J18*0.9 -> 16740.392 | L18: =K18*0.9 -> 15066.352 | ... O18: =N18*0.9 -> 10983.371
C19: Profit Margin(BEV) | D19: =D15-D16-D17-D18 -> 8544.85 | E19: =E15-E16-E17-E18 -> 10633.79 | F19: =F15-F16-F17-F18 -> -17932.694 | G19: =G15-G16-G17-G18 -> -16234.06 | H19: =H15-H16-H17-H18 -> -14701.819 | I19: =I15-I16-I17-I18 -> -13319.332 | J19: =J15-J16-J17-J18 -> -12071.624 | K19: =K15-K16-K17-K18 -> -10945.216 | ... O19: =O15-O16-O17-O18 -> -7427.4728
C20: PM/Revenue | D20: =D19/D14 -> 0.05237259 | E20: =E19/E14 -> 0.070089641 | F20: =F19/F14 -> -0.16853434 | G20: =G19/G14 -> -0.16718405 | H20: =H19/H14 -> -0.16572315 | I20: =I19/I14 -> -0.16414577 | J20: =J19/J14 -> -0.16244627 | K20: =K19/K14 -> -0.16061932 | ... O20: =O19/O14 -> -0.1519457
C21: BYD Pro
D22: 2019 | E22: 2020 | F22: 2021 | G22: 2022 | H22: 2023 | I22: 2024 | J22: 2025 | K22: 2026 | L22: 2027 | M22: 2028 | N22: 2029 | O22: 2030
C23: Retail Price | D23: 137900 | E23: =D23+(E29-D29)+(E30-D30) -> 138500 | F23: =E23+(F29-E29)+(F30-E30) -> 139112 | G23: =F23+(G29-F29)+(G30-F30) -> 139736.24 | H23: =G23+(H29-G29)+(H30-G30) -> 140372.96 | I23: =H23+(I29-H29)+(I30-H30) -> 141022.42 | J23: =I23+(J29-I29)+(J30-I30) -> 141684.87 | K23: =J23+(K29-J29)+(K30-J30) -> 142360.57 | L23: =K23+(L29-K29)+(L30-K30) -> 143049.78 | ... O23: =N23+(O29-N29)+(O30-N30) -> 145201.23
C24: Purchase Tax | D24: =D23*0.1 -> 13790 | E24: =E23*0.1 -> 13850 | F24: =F23*0.1 -> 13911.2 | G24: =G23*0.1 -> 13973.624 | H24: =H23*0.1 -> 14037.296 | I24: =I23*0.1 -> 14102.242 | J24: =J23*0.1 -> 14168.487 | K24: =K23*0.1 -> 14236.057 | ... O24: =O23*0.1 -> 14520.123
C25: Consumer Final Price | D25: =D23+D24 -> 151690 | E25: =E23+E24 -> 152350 | F25: =F23+F24 -> 153023.2 | G25: =G23+G24 -> 153709.86 | H25: =H23+H24 -> 154410.26 | I25: =I23+I24 -> 155124.67 | J25: =J23+J24 -> 155853.36 | K25: =K23+K24 -> 156596.63 | ... O25: =O23+O24 -> 159721.35
C26: Dealer Gross Profit (5%) | D26: =D23*0.05 -> 6895 | E26: =E23*0.05 -> 6925 | F26: =F23*0.05 -> 6955.6 | G26: =G23*0.05 -> 6986.812 | H26: =H23*0.05 -> 7018.6482 | I26: =I23*0.05 -> 7051.1212 | J26: =J23*0.05 -> 7084.2436 | K26: =K23*0.05 -> 7118.0285 | ... O26: =O23*0.05 -> 7260.0615
C27: Auto Company Revenue | D27: =D23-D26 -> 131005 | E27: =E23-E26 -> 131575 | F27: =F23-F26 -> 132156.4 | G27: =G23-G26 -> 132749.43 | H27: =H23-H26 -> 133354.32 | I27: =I23-I26 -> 133971.3 | J27: =J23-J26 -> 134600.63 | K27: =K23-K26 -> 135242.54 | ... O27: =O23-O26 -> 137941.17
C28: Revenue (after vat) | D28: =D27*0.87 -> 113974.35 | E28: =E27*0.87 -> 114470.25 | F28: =F27*0.87 -> 114976.07 | G28: =G27*0.87 -> 115492 | H28: =H27*0.87 -> 116018.26 | I28: =I27*0.87 -> 116555.03 | J28: =J27*0.87 -> 117102.55 | K28: =K27*0.87 -> 117661.01 | ... O28: =O27*0.87 -> 120008.82
C29: Motor Cost | D29: 20000 | E29: =D29*1.02 -> 20400 | F29: =E29*1.02 -> 20808 | G29: =F29*1.02 -> 21224.16 | H29: =G29*1.02 -> 21648.643 | I29: =H29*1.02 -> 22081.616 | J29: =I29*1.02 -> 22523.248 | K29: =J29*1.02 -> 22973.713 | L29: =K29*1.02 -> 23433.188 | ... O29: =N29*1.02 -> 24867.486
C30: Transmission Cost | D30: 10000 | E30: =D30*1.02 -> 10200 | F30: =E30*1.02 -> 10404 | G30: =F30*1.02 -> 10612.08 | H30: =G30*1.02 -> 10824.322 | I30: =H30*1.02 -> 11040.808 | J30: =I30*1.02 -> 11261.624 | K30: =J30*1.02 -> 11486.857 | L30: =K30*1.02 -> 11716.594 | ... O30: =N30*1.02 -> 12433.743
C31: 48V System Cost | D31: 4000 | E31: 4000 | F31: 4000 | G31: 4000 | H31: 4000 | I31: 4000 | J31: 4000 | K31: 4000 | L31: 4000 | M31: 4000 | N31: 4000 | O31: 4000
C32: Other Cost | D32: 40000 | E32: 40000 | F32: 40000 | G32: 40000 | H32: 40000 | I32: 40000 | J32: 40000 | K32: 40000 | L32: 40000 | M32: 40000 | N32: 40000 | O32: 40000
C33: Profit Margin(ICEV) | D33: =D28-D29-D30-D31-D32 -> 39974.35 | E33: =E28-E29-E30-E31-E32 -> 39870.25 | F33: =F28-F29-F30-F31-F32 -> 39764.068 | G33: =G28-G29-G30-G31-G32 -> 39655.762 | H33: =H28-H29-H30-H31-H32 -> 39545.291 | I33: =I28-I29-I30-I31-I32 -> 39432.609 | J33: =J28-J29-J30-J31-J32 -> 39317.675 | K33: =K28-K29-K30-K31-K32 -> 39200.441 | ... O33: =O28-O29-O30-O31-O32 -> 38707.587
C34: PM/Revenue | D34: =D33/D27 -> 0.30513606 | E34: =E33/E27 -> 0.30302299 | F34: =F33/F27 -> 0.30088643 | G34: =G33/G27 -> 0.29872643 | H34: =H33/H27 -> 0.29654301 | I34: =I33/I27 -> 0.29433624 | J34: =J33/J27 -> 0.29210617 | K34: =K33/K27 -> 0.28985289 | ... O34: =O33/O27 -> 0.28060939
D35: =D8-D25 -> -16790 | E35: =E8-E25 -> -29490 | F35: =F8-F25 -> -29818.8 | G35: =G8-G25 -> -41274.904 | H35: =H8-H25 -> -51689.797 | I35: =I8-I25 -> -61169.249 | J35: =J8-J25 -> -69808.484 | K35: =K8-K25 -> -77693.239 | ... O35: =O8-O25 -> -103120.66
D36: 2019 | E36: 2020 | F36: 2021 | G36: 2022 | H36: 2023 | I36: 2024 | J36: 2025 | K36: 2026 | L36: 2027 | M36: 2028 | N36: 2029 | O36: 2030
B38: ICEV BEV | D38: BYD Qin Pro EV-Supreme 比亚迪秦Pro EV | E38: BYD QIN EV 比亚迪秦EV | F38: BYD QIN EV450 比亚迪秦EV450 | G38: BAIC EU7 北汽EU7 | H38: JAC iC5 江淮iC5 | I38: JAC iEVA50 江淮iEVA50 | J38: Nissan Sylphy 尼桑轩逸 | K38: GAC NE GE3 广汽新能源GE3 | L38: Tesla Model 3 特斯拉 Model 3 | M38: Hyundai lafesta ev 现代菲斯塔 | N38: Toyota IZOA 丰田奕泽 | O38: Ford Territory EV （SUV） 福特领界 | P38: Weltmeister EX6 （SUV） 威马EX6 | Q38: Weltmeister EX5 （SUV） 威马EX5 | R38: Roewe RX5 eMax （SUV） 荣威RX5 | S38: Changan EADO EV460 长安逸动EV460
D39: 199900 | E39: 164850 | F39: 184900 | G39: 167900 | H39: 167500 | I39: 142500 | J39: 169500 | K39: 163300 | L39: 404475 | M39: 186300 | N39: 174800 | O39: 202900 | P39: 214900 | Q39: 164800 | R39: 215800 | S39: 134900 | U39: =_xlfn.STDEV.P(Q39,P39,O39,N39,M39,K39,J39,H39,G39,F39,E39,D39) -> 16786.235
B40: BYD QIN PRO 比亚迪秦Pro | C40: 97800 | D40: Post 2030 | E40: 2026 | F40: 2030 | G40: 2027 | H40: 2027 | I40: 2024 | J40: 2027 | K40: 2026 | L40: Post 2030 | M40: 2030 | N40: 2029 | O40: Post 2030 | P40: Post 2030 | Q40: 2026 | R40: Post 2030 | S40: 2023
B41: BYD QIN 比亚迪秦 | C41: 73400 | D41: Post 2030 | E41: Post 2030 | F41: Post 2030 | G41: Post 2030 | H41: Post 2030 | I41: 2028 | J41: Post 2030 | K41: 2030 | L41: Post 2030 | M41: Post 2030 | N41: Post 2030 | O41: Post 2030 | P41: Post 2030 | Q41: Post 2030 | R41: Post 2030 | S41: 2026
B42: JAC Jiayue A5 江淮嘉悦A5 | C42: 100300 | D42: Post 2030 | E42: 2026 | F42: 2029 | G42: 2026 | H42: 2026 | I42: 2023 | J42: 2027 | K42: 2026 | L42: Post 2030 | M42: 2030 | N42: 2029 | O42: Post 2030 | P42: Post 2030 | Q42: 2026 | R42: Post 2030 | S42: 2023
B43: JAC S7 （SUV） 江淮瑞风 | C43: 124800 | D43: 2028 | E43: 2023 | F43: 2025 | G43: 2023 | H43: 2023 | I43: 2020 | J43: 2024 | K43: 2023 | L43: Post 2030 | M43: 2026 | N43: 2025 | O43: 2028 | P43: 2030 | Q43: 2023 | R43: Post 2030 | S43: 2019
B44: BAIC D70 北汽D70 | C44: 175800 | D44: 2020 | E44: 2019 | F44: 2019 | G44: 2019 | H44: 2019 | I44: 2019 | J44: 2019 | K44: 2019 | L44: Post 2030 | M44: 2019 | N44: 2019 | O44: 2020 | P44: 2023 | Q44: 2019 | R44: 2023 | S44: 2019
...

Sheet C
C4: Audi e-tron 55 quattro
D5: 2019 | E5: 2020 | F5: 2021 | G5: 2022 | H5: 2023 | I5: 2024 | J5: 2025 | K5: 2026 | L5: 2027 | M5: 2028 | N5: 2029 | O5: 2030
C6: Retail Price | D6: 658800 | E6: =D6-((D16-E16)+(D17-E17)+(D18-E18)) -> 642200 | F6: =E6-((E16-F16)+(E17-F17)+(E18-F18)) -> 627240 | G6: =F6-((F16-G16)+(F17-G17)+(F18-G18)) -> 613756 | H6: =G6-((G16-H16)+(G17-H17)+(G18-H18)) -> 601600.4 | I6: =H6-((H16-I16)+(H17-I17)+(H18-I18)) -> 590640.36 | J6: =I6-((I16-J16)+(I17-J17)+(I18-J18)) -> 580756.32 | K6: =J6-((J16-K16)+(J17-K17)+(J18-K18)) -> 571840.69 | L6: =K6-((K16-L16)+(K17-L17)+(K18-L18)) -> 563796.62 | ... O6: =N6-((N16-O16)+(N17-O17)+(N18-O18)) -> 544064.94
C7: Purchase Tax | D7: 0 | E7: 0 | F7: =F6*0.1 -> 62724 | G7: =G6*0.1 -> 61375.6 | H7: =H6*0.1 -> 60160.04 | I7: =I6*0.1 -> 59064.036 | J7: =J6*0.1 -> 58075.632 | K7: =K6*0.1 -> 57184.069 | L7: =L6*0.1 -> 56379.662 | M7: =M6*0.1 -> 55653.696 | ... O7: =O6*0.1 -> 54406.494
C8: Consumer Final Price | D8: =D6+D7 -> 658800 | E8: =E6+E7 -> 642200 | F8: =F6+F7 -> 689964 | G8: =G6+G7 -> 675131.6 | H8: =H6+H7 -> 661760.44 | I8: =I6+I7 -> 649704.4 | J8: =J6+J7 -> 638831.96 | K8: =K6+K7 -> 629024.76 | ... O8: =O6+O7 -> 598471.43
C9: Dealer Gross Profit(5%) | D9: =D6*0.05 -> 32940 | E9: =E6*0.05 -> 32110 | F9: =F6*0.05 -> 31362 | G9: =G6*0.05 -> 30687.8 | H9: =H6*0.05 -> 30080.02 | I9: =I6*0.05 -> 29532.018 | J9: =J6*0.05 -> 29037.816 | K9: =K6*0.05 -> 28592.035 | ... O9: =O6*0.05 -> 27203.247
C10: Range (km) | D10: 470 | E10: 470 | F10: 470 | G10: 470 | H10: 470 | I10: 470 | J10: 470 | K10: 470 | L10: 470 | M10: 470 | N10: 470 | O10: 470
C11: Battery (kwh) | D11: 95 | E11: 95 | F11: 95 | G11: 95 | H11: 95 | I11: 95 | J11: 95 | K11: 95 | L11: 95 | M11: 95 | N11: 95 | O11: 95
C12: Battery Price/wh | D12: 1.2 | E12: =D12*0.9 -> 1.08 | F12: =E12*0.9 -> 0.972 | G12: =F12*0.9 -> 0.8748 | H12: =G12*0.9 -> 0.78732 | I12: =H12*0.9 -> 0.708588 | J12: =I12*0.9 -> 0.6377292 | K12: =J12*0.9 -> 0.57395628 | L12: =K12*0.9 -> 0.51656065 | ... O12: =N12*0.9 -> 0.37657272
C13: Subsidies | D13: 35000 | E13: 35000 | F13: 0 | G13: 0 | H13: 0 | I13: 0 | J13: 0 | K13: 0 | L13: 0 | M13: 0 | N13: 0 | O13: 0
C14: Auto Company Revenue | D14: =D6-D9+D13 -> 660860 | E14: =E6-E9+E13 -> 645090 | F14: =F6-F9+F13 -> 595878 | G14: =G6-G9+G13 -> 583068.2 | H14: =H6-H9+H13 -> 571520.38 | I14: =I6-I9+I13 -> 561108.34 | J14: =J6-J9+J13 -> 551718.51 | K14: =K6-K9+K13 -> 543248.66 | ... O14: =O6-O9+O13 -> 516861.69
C15: Revenue (after vat) | D15: =D14*0.87 -> 574948.2 | E15: =E14*0.87 -> 561228.3 | F15: =F14*0.87 -> 518413.86 | G15: =G14*0.87 -> 507269.33 | H15: =H14*0.87 -> 497222.73 | I15: =I14*0.87 -> 488164.26 | J15: =J14*0.87 -> 479995.1 | K15: =K14*0.87 -> 472626.33 | ... O15: =O14*0.87 -> 449669.67
C16: Power Battery System Cost | D16: =D12*1000*D11 -> 114000 | E16: =E12*1000*E11 -> 102600 | F16: =F12*1000*F11 -> 92340 | G16: =G12*1000*G11 -> 83106 | H16: =H12*1000*H11 -> 74795.4 | I16: =I12*1000*I11 -> 67315.86 | J16: =J12*1000*J11 -> 60584.274 | K16: =K12*1000*K11 -> 54525.847 | ... O16: =O12*1000*O11 -> 35774.408
C17: Electric Motor & Electric Controlling | D17: 30000 | E17: =D17-200 -> 29800 | F17: =E17-200 -> 29600 | G17: =F17-200 -> 29400 | H17: =G17-200 -> 29200 | I17: =H17-200 -> 29000 | J17: =I17-200 -> 28800 | K17: =J17-200 -> 28600 | L17: =K17-200 -> 28400 | ... O17: =N17-200 -> 27800
C18: Other Cost | D18: 50000 | E18: =D18*0.9 -> 45000 | F18: =E18*0.9 -> 40500 | G18: =F18*0.9 -> 36450 | H18: =G18*0.9 -> 32805 | I18: =H18*0.9 -> 29524.5 | J18: =I18*0.9 -> 26572.05 | K18: =J18*0.9 -> 23914.845 | L18: =K18*0.9 -> 21523.361 | ... O18: =N18*0.9 -> 15690.53
C19: Profit Margin(BEV) | D19: =D15-D16-D17-D18 -> 380948.2 | E19: =E15-E16-E17-E18 -> 383828.3 | F19: =F15-F16-F17-F18 -> 355973.86 | G19: =G15-G16-G17-G18 -> 358313.33 | H19: =H15-H16-H17-H18 -> 360422.33 | I19: =I15-I16-I17-I18 -> 362323.9 | J19: =J15-J16-J17-J18 -> 364038.78 | K19: =K15-K16-K17-K18 -> 365585.64 | ... O19: =O15-O16-O17-O18 -> 370404.73
C20: PM/Revenue | D20: =D19/D14 -> 0.57644312 | E20: =E19/E14 -> 0.59499961 | F20: =F19/F14 -> 0.59739386 | G20: =G19/G14 -> 0.61453074 | H20: =H19/H14 -> 0.63063776 | I20: =I19/I14 -> 0.64572894 | J20: =J19/J14 -> 0.65982702 | K20: =K19/K14 -> 0.67296188 | ... O20: =O19/O14 -> 0.71664188
C21: Audi A6 all-road quattro
D22: 2019 | E22: 2020 | F22: 2021 | G22: 2022 | H22: 2023 | I22: 2024 | J22: 2025 | K22: 2026 | L22: 2027 | M22: 2028 | N22: 2029 | O22: 2030
C23: Retail Price | D23: 546800 | E23: =D23+(E29-D29)+(E30-D30) -> 549400 | F23: =E23+(F29-E29)+(F30-E30) -> 552052 | G23: =F23+(G29-F29)+(G30-F30) -> 554757.04 | H23: =G23+(H29-G29)+(H30-G30) -> 557516.18 | I23: =H23+(I29-H29)+(I30-H30) -> 560330.5 | J23: =I23+(J29-I29)+(J30-I30) -> 563201.11 | K23: =J23+(K29-J29)+(K30-J30) -> 566129.14 | L23: =K23+(L29-K29)+(L30-K30) -> 569115.72 | ... O23: =N23+(O29-N29)+(O30-N30) -> 578438.66
C24: Purchase Tax | D24: =D23*0.1 -> 54680 | E24: =E23*0.1 -> 54940 | F24: =F23*0.1 -> 55205.2 | G24: =G23*0.1 -> 55475.704 | H24: =H23*0.1 -> 55751.618 | I24: =I23*0.1 -> 56033.05 | J24: =J23*0.1 -> 56320.111 | K24: =K23*0.1 -> 56612.914 | ... O24: =O23*0.1 -> 57843.866
C25: Consumer Final Price | D25: =D23+D24 -> 601480 | E25: =E23+E24 -> 604340 | F25: =F23+F24 -> 607257.2 | G25: =G23+G24 -> 610232.74 | H25: =H23+H24 -> 613267.8 | I25: =I23+I24 -> 616363.55 | J25: =J23+J24 -> 619521.23 | K25: =K23+K24 -> 622742.05 | ... O25: =O23+O24 -> 636282.53
